Workbook

Sheet START HERE
A1: Item | B1: Updated assessment
A2: Project | B2: Vietnamese depression-related language — updated descriptive mixed-methods triangulation
A3: Core MAXQDA source | B3: Vietnamese_Depression_Label1_231_Texts_15_Codes_Reviewed_Baseline.qdpx
A4: Export used for cross-check | B4: maxqda_export.xlsx and underlying 245-document source linkage
A5: Codebook provenance | B5: Human-developed codebook per corresponding researcher confirmation
A6: Coding provenance | B6: AI-assisted initial placement, revised, subsequently validated by researcher (user-reported). QDPX still contains original AI-assistance metadata.
A7: Retained Label 1 documents | B7: 231
A8: Original purposive sample | B8: 245
A9: Post hoc exclusions (uncoded) | B9: 14
A10: Retained thematic codes | B10: 15
A11: Coded passages | B11: 523
A12: LDA-dominant-topic coverage | B12: 231
A13: GPT-covered unique documents | B13: 182
A14: GPT primary-theme annotation records | B14: 210
A15: One GPT annotation (texts) | B15: 154
A16: Two GPT annotations (texts) | B16: 28
A17: No GPT annotation (texts) | B17: 49
A18: Important denominator change | B18: Excluding 14 texts without MAXQDA codes does not change any MAXQDA–LDA/GPT overlap numerator; it changes topic denominators.
A19: Warning: study design | B19: The 231-text analysis is a post-exclusion subset of an original 245-text purposive sample. Report exclusion criteria transparently and consider original-sample sensitivity analysis.
A20: Scope | B20: Descriptive thematic co-occurrence / overlap only; neither diagnosis nor accuracy/independent agreement.
A21: LDA unit | B21: Unique texts, one dominant LDA topic per text; multiple MAXQDA codes may appear within a text.
A22: GPT unit | B22: Annotation records from D1/D2, 210 total from 182 unique texts; same text can contribute twice.
A23: Data integrity | B23: 231/231 internal text files match source; 523 coding links have valid spans and match the MAXQDA export.

Sheet THEME FREQUENCIES
A1: MAXQDA thematic code | B1: Coded passages | C1: Coded documents | D1: Share of retained 231 texts
A2: Emotional Distress | B2: 33 | C2: 33 | D2: =C2/231 -> 0.14285714
A3: Negative Self-Perception | B3: 16 | C3: 16 | D3: =C3/231 -> 0.069264069
A4: Hopelessness & Loss of Interest | B4: 11 | C4: 11 | D4: =C4/231 -> 0.047619048
A5: Relationships & Isolation | B5: 31 | C5: 31 | D5: =C5/231 -> 0.13419913
A6: Family & Parenting | B6: 33 | C6: 33 | D6: =C6/231 -> 0.14285714
A7: Work, Study & Financial Stress | B7: 28 | C7: 28 | D7: =C7/231 -> 0.12121212
A8: Sleep & Physical Difficulties | B8: 42 | C8: 42 | D8: =C8/231 -> 0.18181818
A9: Anxiety & Fear | B9: 89 | C9: 89 | D9: =C9/231 -> 0.38528139
A10: Treatment & Medication | B10: 72 | C10: 72 | D10: =C10/231 -> 0.31168831
A11: Help-Seeking, Coping & Support | B11: 39 | C11: 39 | D11: =C11/231 -> 0.16883117
A12: Alcohol & Substance Use | B12: 16 | C12: 16 | D12: =C12/231 -> 0.069264069
A13: Self-Harm & Suicidal Thoughts | B13: 41 | C13: 41 | D13: =C13/231 -> 0.17748918
... A16: Casual or Figurative Depression Language | B16: 30 | C16: 30 | D16: =C16/231 -> 0.12987013

Sheet LDA KEY COMPARISONS
A1: LDA topic | B1: Topic description | C1: Original topic n | D1: Retained topic n | E1: Related MAXQDA theme | F1: Coded texts | G1: Overlap / 231 subset | H1: Overlap / original 245 subset | I1: Change (percentage points) | J1: Interpretive caveat
A2: LDA 1 | B2: Medication and Psychiatric Treatment Management | C2: 31 | D2: 30 | E2: Treatment & Medication | F2: 26 | G2: =F2/D2 -> 0.86666667 | H2: =F2/C2 -> 0.83870968 | I2: =(G2-H2)*100 -> 2.7956989 | J2: Related category; overlap, not a one-to-one agreement score
A3: LDA 2 | B3: Anxiety, Panic, and Somatic Symptoms | C3: 40 | D3: 35 | E3: Anxiety & Fear | F3: 28 | G3: =F3/D3 -> 0.8 | H3: =F3/C3 -> 0.7 | I3: =(G3-H3)*100 -> 10 | J3: Related category; overlap, not a one-to-one agreement score
A4: LDA 2 | B4: Anxiety, Panic, and Somatic Symptoms | C4: 40 | D4: 35 | E4: Sleep & Physical Difficulties | F4: 24 | G4: =F4/D4 -> 0.68571429 | H4: =F4/C4 -> 0.6 | I4: =(G4-H4)*100 -> 8.5714286 | J4: Related category; overlap, not a one-to-one agreement score
A5: LDA 3 | B5: Psychosocial Stressors and Functional Impairment | C5: 45 | D5: 44 | E5: Work, Study & Financial Stress | F5: 20 | G5: =F5/D5 -> 0.45454545 | H5: =F5/C5 -> 0.44444444 | I5: =(G5-H5)*100 -> 1.010101 | J5: Related category; overlap, not a one-to-one agreement score
A6: LDA 3 | B6: Psychosocial Stressors and Functional Impairment | C6: 45 | D6: 44 | E6: Family & Parenting | F6: 15 | G6: =F6/D6 -> 0.34090909 | H6: =F6/C6 -> 0.33333333 | I6: =(G6-H6)*100 -> 0.75757576 | J6: Related category; overlap, not a one-to-one agreement score
A7: LDA 4 | B7: Event-Specific Public Discourse | C7: 10 | D7: 10 | E7: Public Discussion of Depression | F7: 8 | G7: =F7/D7 -> 0.8 | H7: =F7/C7 -> 0.8 | I7: =(G7-H7)*100 -> 0 | J7: Related category; overlap, not a one-to-one agreement score
A8: LDA 5 | B8: Help-Seeking, Mental-Health Information, and Community Support | C8: 40 | D8: 36 | E8: Help-Seeking, Coping & Support | F8: 10 | G8: =F8/D8 -> 0.27777778 | H8: =F8/C8 -> 0.25 | I8: =(G8-H8)*100 -> 2.7777778 | J8: Related category; overlap, not a one-to-one agreement score
A9: LDA 6 | B9: Event-Specific Social-Media Commentary and Depression Trivialization | C9: 30 | D9: 29 | E9: Casual or Figurative Depression Language | F9: 22 | G9: =F9/D9 -> 0.75862069 | H9: =F9/C9 -> 0.73333333 | I9: =(G9-H9)*100 -> 2.5287356 | J9: Related category; overlap, not a one-to-one agreement score
A10: LDA 7 | B10: Severe Depressive Distress, Hopelessness, and Suicidality | C10: 49 | D10: 47 | E10: Self-Harm & Suicidal Thoughts | F10: 20 | G10: =F10/D10 -> 0.42553191 | H10: =F10/C10 -> 0.40816327 | I10: =(G10-H10)*100 -> 1.736865 | J10: Related category; overlap, not a one-to-one agreement score

Sheet LDA FULL MATRIX
A1: MAXQDA theme | B1: T1 (n=30) | C1: T2 (n=35) | D1: T3 (n=44) | E1: T4 (n=10) | F1: T5 (n=36) | G1: T6 (n=29) | H1: T7 (n=47) | I1: Total segments
A2: Emotional Distress | B2: 2 | C2: 3 | D2: 11 | E2: 0 | F2: 2 | G2: 1 | H2: 14 | I2: 33
A3: Negative Self-Perception | B3: 0 | C3: 1 | D3: 5 | E3: 0 | F3: 1 | G3: 0 | H3: 9 | I3: 16
A4: Hopelessness & Loss of Interest | B4: 0 | C4: 1 | D4: 2 | E4: 0 | F4: 0 | G4: 0 | H4: 8 | I4: 11
A5: Relationships & Isolation | B5: 1 | C5: 3 | D5: 9 | E5: 1 | F5: 3 | G5: 1 | H5: 13 | I5: 31
A6: Family & Parenting | B6: 1 | C6: 1 | D6: 15 | E6: 0 | F6: 6 | G6: 2 | H6: 8 | I6: 33
A7: Work, Study & Financial Stress | B7: 1 | C7: 4 | D7: 20 | E7: 0 | F7: 1 | G7: 0 | H7: 2 | I7: 28
A8: Sleep & Physical Difficulties | B8: 5 | C8: 24 | D8: 6 | E8: 0 | F8: 2 | G8: 0 | H8: 5 | I8: 42
A9: Anxiety & Fear | B9: 13 | C9: 28 | D9: 20 | E9: 0 | F9: 18 | G9: 0 | H9: 10 | I9: 89
A10: Treatment & Medication | B10: 26 | C10: 17 | D10: 5 | E10: 0 | F10: 14 | G10: 1 | H10: 9 | I10: 72
A11: Help-Seeking, Coping & Support | B11: 3 | C11: 7 | D11: 7 | E11: 0 | F11: 10 | G11: 1 | H11: 11 | I11: 39
A12: Alcohol & Substance Use | B12: 2 | C12: 3 | D12: 3 | E12: 0 | F12: 5 | G12: 0 | H12: 3 | I12: 16
A13: Self-Harm & Suicidal Thoughts | B13: 3 | C13: 1 | D13: 14 | E13: 0 | F13: 3 | G13: 0 | H13: 20 | I13: 41
... A16: Casual or Figurative Depression Language | B16: 0 | C16: 2 | D16: 4 | E16: 1 | F16: 0 | G16: 22 | H16: 1 | I16: 30

Sheet LDA WITHIN-TOPIC RATES
A1: MAXQDA theme | B1: T1 (%) | C1: T2 (%) | D1: T3 (%) | E1: T4 (%) | F1: T5 (%) | G1: T6 (%) | H1: T7 (%)
A2: Emotional Distress | B2: ='LDA FULL MATRIX'!B2/30 -> 0.066666667 | C2: ='LDA FULL MATRIX'!C2/35 -> 0.085714286 | D2: ='LDA FULL MATRIX'!D2/44 -> 0.25 | E2: ='LDA FULL MATRIX'!E2/10 -> 0 | F2: ='LDA FULL MATRIX'!F2/36 -> 0.055555556 | G2: ='LDA FULL MATRIX'!G2/29 -> 0.034482759 | H2: ='LDA FULL MATRIX'!H2/47 -> 0.29787234
A3: Negative Self-Perception | B3: ='LDA FULL MATRIX'!B3/30 -> 0 | C3: ='LDA FULL MATRIX'!C3/35 -> 0.028571429 | D3: ='LDA FULL MATRIX'!D3/44 -> 0.11363636 | E3: ='LDA FULL MATRIX'!E3/10 -> 0 | F3: ='LDA FULL MATRIX'!F3/36 -> 0.027777778 | G3: ='LDA FULL MATRIX'!G3/29 -> 0 | H3: ='LDA FULL MATRIX'!H3/47 -> 0.19148936
A4: Hopelessness & Loss of Interest | B4: ='LDA FULL MATRIX'!B4/30 -> 0 | C4: ='LDA FULL MATRIX'!C4/35 -> 0.028571429 | D4: ='LDA FULL MATRIX'!D4/44 -> 0.045454545 | E4: ='LDA FULL MATRIX'!E4/10 -> 0 | F4: ='LDA FULL MATRIX'!F4/36 -> 0 | G4: ='LDA FULL MATRIX'!G4/29 -> 0 | H4: ='LDA FULL MATRIX'!H4/47 -> 0.17021277
A5: Relationships & Isolation | B5: ='LDA FULL MATRIX'!B5/30 -> 0.033333333 | C5: ='LDA FULL MATRIX'!C5/35 -> 0.085714286 | D5: ='LDA FULL MATRIX'!D5/44 -> 0.20454545 | E5: ='LDA FULL MATRIX'!E5/10 -> 0.1 | F5: ='LDA FULL MATRIX'!F5/36 -> 0.083333333 | G5: ='LDA FULL MATRIX'!G5/29 -> 0.034482759 | H5: ='LDA FULL MATRIX'!H5/47 -> 0.27659574
A6: Family & Parenting | B6: ='LDA FULL MATRIX'!B6/30 -> 0.033333333 | C6: ='LDA FULL MATRIX'!C6/35 -> 0.028571429 | D6: ='LDA FULL MATRIX'!D6/44 -> 0.34090909 | E6: ='LDA FULL MATRIX'!E6/10 -> 0 | F6: ='LDA FULL MATRIX'!F6/36 -> 0.16666667 | G6: ='LDA FULL MATRIX'!G6/29 -> 0.068965517 | H6: ='LDA FULL MATRIX'!H6/47 -> 0.17021277
A7: Work, Study & Financial Stress | B7: ='LDA FULL MATRIX'!B7/30 -> 0.033333333 | C7: ='LDA FULL MATRIX'!C7/35 -> 0.11428571 | D7: ='LDA FULL MATRIX'!D7/44 -> 0.45454545 | E7: ='LDA FULL MATRIX'!E7/10 -> 0 | F7: ='LDA FULL MATRIX'!F7/36 -> 0.027777778 | G7: ='LDA FULL MATRIX'!G7/29 -> 0 | H7: ='LDA FULL MATRIX'!H7/47 -> 0.042553191
A8: Sleep & Physical Difficulties | B8: ='LDA FULL MATRIX'!B8/30 -> 0.16666667 | C8: ='LDA FULL MATRIX'!C8/35 -> 0.68571429 | D8: ='LDA FULL MATRIX'!D8/44 -> 0.13636364 | E8: ='LDA FULL MATRIX'!E8/10 -> 0 | F8: ='LDA FULL MATRIX'!F8/36 -> 0.055555556 | G8: ='LDA FULL MATRIX'!G8/29 -> 0 | H8: ='LDA FULL MATRIX'!H8/47 -> 0.10638298
A9: Anxiety & Fear | B9: ='LDA FULL MATRIX'!B9/30 -> 0.43333333 | C9: ='LDA FULL MATRIX'!C9/35 -> 0.8 | D9: ='LDA FULL MATRIX'!D9/44 -> 0.45454545 | E9: ='LDA FULL MATRIX'!E9/10 -> 0 | F9: ='LDA FULL MATRIX'!F9/36 -> 0.5 | G9: ='LDA FULL MATRIX'!G9/29 -> 0 | H9: ='LDA FULL MATRIX'!H9/47 -> 0.21276596
A10: Treatment & Medication | B10: ='LDA FULL MATRIX'!B10/30 -> 0.86666667 | C10: ='LDA FULL MATRIX'!C10/35 -> 0.48571429 | D10: ='LDA FULL MATRIX'!D10/44 -> 0.11363636 | E10: ='LDA FULL MATRIX'!E10/10 -> 0 | F10: ='LDA FULL MATRIX'!F10/36 -> 0.38888889 | G10: ='LDA FULL MATRIX'!G10/29 -> 0.034482759 | H10: ='LDA FULL MATRIX'!H10/47 -> 0.19148936
A11: Help-Seeking, Coping & Support | B11: ='LDA FULL MATRIX'!B11/30 -> 0.1 | C11: ='LDA FULL MATRIX'!C11/35 -> 0.2 | D11: ='LDA FULL MATRIX'!D11/44 -> 0.15909091 | E11: ='LDA FULL MATRIX'!E11/10 -> 0 | F11: ='LDA FULL MATRIX'!F11/36 -> 0.27777778 | G11: ='LDA FULL MATRIX'!G11/29 -> 0.034482759 | H11: ='LDA FULL MATRIX'!H11/47 -> 0.23404255
A12: Alcohol & Substance Use | B12: ='LDA FULL MATRIX'!B12/30 -> 0.066666667 | C12: ='LDA FULL MATRIX'!C12/35 -> 0.085714286 | D12: ='LDA FULL MATRIX'!D12/44 -> 0.068181818 | E12: ='LDA FULL MATRIX'!E12/10 -> 0 | F12: ='LDA FULL MATRIX'!F12/36 -> 0.13888889 | G12: ='LDA FULL MATRIX'!G12/29 -> 0 | H12: ='LDA FULL MATRIX'!H12/47 -> 0.063829787
A13: Self-Harm & Suicidal Thoughts | B13: ='LDA FULL MATRIX'!B13/30 -> 0.1 | C13: ='LDA FULL MATRIX'!C13/35 -> 0.028571429 | D13: ='LDA FULL MATRIX'!D13/44 -> 0.31818182 | E13: ='LDA FULL MATRIX'!E13/10 -> 0 | F13: ='LDA FULL MATRIX'!F13/36 -> 0.083333333 | G13: ='LDA FULL MATRIX'!G13/29 -> 0 | H13: ='LDA FULL MATRIX'!H13/47 -> 0.42553191
... A16: Casual or Figurative Depression Language | B16: ='LDA FULL MATRIX'!B16/30 -> 0 | C16: ='LDA FULL MATRIX'!C16/35 -> 0.057142857 | D16: ='LDA FULL MATRIX'!D16/44 -> 0.090909091 | E16: ='LDA FULL MATRIX'!E16/10 -> 0.1 | F16: ='LDA FULL MATRIX'!F16/36 -> 0 | G16: ='LDA FULL MATRIX'!G16/29 -> 0.75862069 | H16: ='LDA FULL MATRIX'!H16/47 -> 0.021276596

Sheet GPT KEY COMPARISONS
A1: GPT topic ID | B1: GPT primary theme | C1: Original records | D1: Retained records | E1: Unique retained texts | F1: Related MAXQDA code | G1: Matching records | H1: Record-level overlap | I1: Original-record sensitivity | J1: Public-discussion coded records
A2: T08 | B2: Treatment, therapy, and medication | C2: 33 | D2: 33 | E2: 31 | F2: Treatment & Medication | G2: 27 | H2: =G2/D2 -> 0.81818182 | I2: =G2/C2 -> 0.81818182 | J2: 4
A3: T11 | B3: Self-harm and suicidality | C3: 43 | D3: 42 | E3: 39 | F3: Self-Harm & Suicidal Thoughts | G3: 36 | H3: =G3/D3 -> 0.85714286 | I3: =G3/C3 -> 0.8372093 | J3: 0
A4: T06 | B4: Work, study, and financial/livelihood pressures | C4: 18 | D4: 15 | E4: 13 | F4: Work, Study & Financial Stress | G4: 4 | H4: =G4/D4 -> 0.26666667 | I4: =G4/C4 -> 0.22222222 | J4: 8

Sheet GPT FULL MATRIX
A1: GPT topic ID | B1: GPT primary theme | C1: Original records | D1: Retained records | E1: Unique texts | F1: Emotional Distress | G1: Negative Self-Perception | H1: Hopelessness & Loss of Interest | I1: Relationships & Isolation | J1: Family & Parenting | K1: Work, Study & Financial Stress | L1: Sleep & Physical Difficulties | M1: Anxiety & Fear | N1: Treatment & Medication | O1: Help-Seeking, Coping & Support | P1: Alcohol & Substance Use | Q1: Self-Harm & Suicidal Thoughts | R1: Recovery & Resilience | S1: Public Discussion of Depression | T1: Casual or Figurative Depression Language
A2: T00 | B2: Other/unclear | C2: 2 | D2: 2 | E2: 2 | F2: 0 | G2: 0 | H2: 0 | I2: 0 | J2: 0 | K2: 0 | L2: 0 | M2: 0 | N2: 0 | O2: 0 | P2: 0 | Q2: 0 | R2: 0 | S2: 1 | T2: 1
A3: T01 | B3: Emotions and feelings | C3: 36 | D3: 34 | E3: 32 | F3: 3 | G3: 1 | H3: 1 | I3: 5 | J3: 5 | K3: 4 | L3: 5 | M3: 19 | N3: 6 | O3: 5 | P3: 2 | Q3: 1 | R3: 2 | S3: 5 | T3: 7
A4: T02 | B4: Self-perception and cognitive patterns | C4: 12 | D4: 12 | E4: 10 | F4: 1 | G4: 5 | H4: 0 | I4: 3 | J4: 1 | K4: 2 | L4: 0 | M4: 5 | N4: 1 | O4: 2 | P4: 2 | Q4: 0 | R4: 1 | S4: 1 | T4: 1
A5: T03 | B5: Motivation, hope/hopelessness, and purpose | C5: 11 | D5: 8 | E5: 7 | F5: 3 | G5: 0 | H5: 2 | I5: 2 | J5: 3 | K5: 1 | L5: 1 | M5: 1 | N5: 2 | O5: 1 | P5: 2 | Q5: 0 | R5: 1 | S5: 0 | T5: 1
A6: T04 | B6: Relationships and social connection | C6: 5 | D6: 5 | E6: 5 | F6: 1 | G6: 0 | H6: 0 | I6: 5 | J6: 1 | K6: 0 | L6: 0 | M6: 1 | N6: 0 | O6: 1 | P6: 0 | Q6: 0 | R6: 0 | S6: 0 | T6: 0
A7: T05 | B7: Family and parenting | C7: 10 | D7: 10 | E7: 9 | F7: 2 | G7: 0 | H7: 0 | I7: 2 | J7: 5 | K7: 0 | L7: 2 | M7: 3 | N7: 1 | O7: 1 | P7: 0 | Q7: 0 | R7: 0 | S7: 3 | T7: 4
A8: T06 | B8: Work, study, and financial/livelihood pressures | C8: 18 | D8: 15 | E8: 13 | F8: 0 | G8: 0 | H8: 0 | I8: 0 | J8: 0 | K8: 4 | L8: 2 | M8: 4 | N8: 2 | O8: 2 | P8: 0 | Q8: 0 | R8: 1 | S8: 8 | T8: 0
A9: T07 | B9: Daily functioning, sleep, and physical/vegetative state | C9: 21 | D9: 19 | E9: 16 | F9: 0 | G9: 0 | H9: 0 | I9: 3 | J9: 1 | K9: 3 | L9: 15 | M9: 18 | N9: 7 | O9: 1 | P9: 1 | Q9: 0 | R9: 1 | S9: 0 | T9: 0
A10: T08 | B10: Treatment, therapy, and medication | C10: 33 | D10: 33 | E10: 31 | F10: 1 | G10: 0 | H10: 2 | I10: 1 | J10: 2 | K10: 2 | L10: 4 | M10: 17 | N10: 27 | O10: 7 | P10: 4 | Q10: 3 | R10: 2 | S10: 4 | T10: 0
A11: T09 | B11: Help-seeking, coping, social support, and recovery | C11: 19 | D11: 18 | E11: 16 | F11: 1 | G11: 1 | H11: 0 | I11: 0 | J11: 1 | K11: 1 | L11: 3 | M11: 7 | N11: 2 | O11: 7 | P11: 3 | Q11: 2 | R11: 4 | S11: 3 | T11: 2
A12: T10 | B12: Alcohol and substance use | C12: 3 | D12: 3 | E12: 3 | F12: 0 | G12: 0 | H12: 0 | I12: 1 | J12: 0 | K12: 0 | L12: 1 | M12: 1 | N12: 1 | O12: 0 | P12: 1 | Q12: 0 | R12: 0 | S12: 1 | T12: 1
A13: T11 | B13: Self-harm and suicidality | C13: 43 | D13: 42 | E13: 39 | F13: 16 | G13: 7 | H13: 6 | I13: 11 | J13: 13 | K13: 10 | L13: 6 | M13: 11 | N13: 10 | O13: 5 | P13: 1 | Q13: 36 | R13: 1 | S13: 0 | T13: 0
A14: T12 | B14: General conversation, community, and leisure | C14: 11 | D14: 9 | E14: 8 | F14: 1 | G14: 0 | H14: 0 | I14: 1 | J14: 1 | K14: 0 | L14: 1 | M14: 0 | N14: 0 | O14: 2 | P14: 0 | Q14: 0 | R14: 0 | S14: 1 | T14: 5

Sheet 231 DOCUMENT LINKAGE
A1: QDA ID | B1: Sampling stratum | C1: Dominant LDA | D1: Dominant LDA label | E1: Dominant prob. | F1: MAXQDA code count | G1: MAXQDA codes | H1: GPT annotation count | I1: GPT D1 theme | J1: GPT D2 theme
A2: QDA-001 | B2: Ambiguous LDA | C2: LDA 1 | D2: Medication and Psychiatric Treatment Management | E2: 0.2448 | F2: 5 | G2: Alcohol & Substance Use; Anxiety & Fear; Recovery & Resilience; Self-Harm & Suicidal Thoughts; Treatment & Medication | H2: 1 | I2: Treatment, therapy, and medication
A3: QDA-002 | B3: Ambiguous LDA | C3: LDA 1 | D3: Medication and Psychiatric Treatment Management | E3: 0.2336 | F3: 1 | G3: Public Discussion of Depression | H3: 2 | I3: Emotions and feelings | J3: Work, study, and financial/livelihood pressures
A4: QDA-003 | B4: Ambiguous LDA | C4: LDA 1 | D4: Medication and Psychiatric Treatment Management | E4: 0.2336 | F4: 1 | G4: Public Discussion of Depression | H4: 1 | J4: Work, study, and financial/livelihood pressures
A5: QDA-004 | B5: Ambiguous LDA | C5: LDA 1 | D5: Medication and Psychiatric Treatment Management | E5: 0.2696 | F5: 1 | G5: Treatment & Medication | H5: 1 | J5: Treatment, therapy, and medication
A6: QDA-005 | B6: Ambiguous LDA | C6: LDA 1 | D6: Medication and Psychiatric Treatment Management | E6: 0.2796 | F6: 1 | G6: Treatment & Medication | H6: 1 | I6: Treatment, therapy, and medication
A7: QDA-006 | B7: GPT-covered | C7: LDA 1 | D7: Medication and Psychiatric Treatment Management | E7: 0.2904 | F7: 1 | G7: Treatment & Medication | H7: 1 | J7: Treatment, therapy, and medication
A8: QDA-007 | B8: GPT-covered | C8: LDA 1 | D8: Medication and Psychiatric Treatment Management | E8: 0.3095 | F8: 1 | G8: Treatment & Medication | H8: 1 | I8: Treatment, therapy, and medication
A9: QDA-008 | B9: GPT-covered | C9: LDA 1 | D9: Medication and Psychiatric Treatment Management | E9: 0.3174 | F9: 3 | G9: Help-Seeking, Coping & Support; Self-Harm & Suicidal Thoughts; Treatment & Medication | H9: 1 | I9: Treatment, therapy, and medication
A10: QDA-009 | B10: GPT-covered | C10: LDA 1 | D10: Medication and Psychiatric Treatment Management | E10: 0.3816 | F10: 2 | G10: Sleep & Physical Difficulties; Treatment & Medication | H10: 1 | I10: Treatment, therapy, and medication
A11: QDA-010 | B11: GPT-covered | C11: LDA 1 | D11: Medication and Psychiatric Treatment Management | E11: 0.3237 | F11: 1 | G11: Treatment & Medication | H11: 1 | J11: Self-harm and suicidality
A12: QDA-011 | B12: GPT-covered | C12: LDA 1 | D12: Medication and Psychiatric Treatment Management | E12: 0.3843 | F12: 2 | G12: Anxiety & Fear; Treatment & Medication | H12: 1 | J12: Treatment, therapy, and medication
A13: QDA-012 | B13: Non-GPT fill | C13: LDA 1 | D13: Medication and Psychiatric Treatment Management | E13: 0.3869 | F13: 2 | G13: Anxiety & Fear; Treatment & Medication | H13: 0
A14: QDA-013 | B14: Non-GPT fill | C14: LDA 1 | D14: Medication and Psychiatric Treatment Management | E14: 0.2702 | F14: 2 | G14: Anxiety & Fear; Treatment & Medication | H14: 0
A15: QDA-014 | B15: Non-GPT fill | C15: LDA 1 | D15: Medication and Psychiatric Treatment Management | E15: 0.2884 | F15: 2 | G15: Anxiety & Fear; Treatment & Medication | H15: 0
A16: QDA-015 | B16: Non-GPT fill | C16: LDA 1 | D16: Medication and Psychiatric Treatment Management | E16: 0.2474 | F16: 3 | G16: Anxiety & Fear; Help-Seeking, Coping & Support; Treatment & Medication | H16: 0
A17: QDA-016 | B17: Non-GPT fill | C17: LDA 1 | D17: Medication and Psychiatric Treatment Management | E17: 0.3692 | F17: 1 | G17: Treatment & Medication | H17: 0
A18: QDA-017 | B18: Non-GPT fill | C18: LDA 1 | D18: Medication and Psychiatric Treatment Management | E18: 0.3243 | F18: 2 | G18: Help-Seeking, Coping & Support; Treatment & Medication | H18: 0
A19: QDA-018 | B19: Non-GPT fill | C19: LDA 1 | D19: Medication and Psychiatric Treatment Management | E19: 0.2947 | F19: 3 | G19: Anxiety & Fear; Sleep & Physical Difficulties; Treatment & Medication | H19: 0
A20: QDA-020 | B20: Non-GPT fill | C20: LDA 1 | D20: Medication and Psychiatric Treatment Management | E20: 0.2628 | F20: 1 | G20: Public Discussion of Depression | H20: 0
A21: QDA-021 | B21: Non-GPT fill | C21: LDA 1 | D21: Medication and Psychiatric Treatment Management | E21: 0.222 | F21: 1 | G21: Treatment & Medication | H21: 0
A22: QDA-022 | B22: Non-GPT fill | C22: LDA 1 | D22: Medication and Psychiatric Treatment Management | E22: 0.3475 | F22: 2 | G22: Relationships & Isolation; Treatment & Medication | H22: 0
A23: QDA-023 | B23: Non-GPT fill | C23: LDA 1 | D23: Medication and Psychiatric Treatment Management | E23: 0.2013 | F23: 2 | G23: Anxiety & Fear; Treatment & Medication | H23: 0
A24: QDA-024 | B24: Non-GPT fill | C24: LDA 1 | D24: Medication and Psychiatric Treatment Management | E24: 0.3002 | F24: 5 | G24: Anxiety & Fear; Emotional Distress; Family & Parenting; Treatment & Medication; Work, Study & Financial Stress | H24: 0
... A29: QDA-029 | B29: Representative | C29: LDA 1 | D29: Medication and Psychiatric Treatment Management | E29: 0.4086 | F29: 1 | G29: Treatment & Medication | H29: 0
A30: QDA-030 | B30: Representative | C30: LDA 1 | D30: Medication and Psychiatric Treatment Management | E30: 0.5246 | F30: 3 | G30: Anxiety & Fear; Sleep & Physical Difficulties; Treatment & Medication | H30: 1 | J30: Treatment, therapy, and medication
A31: QDA-031 | B31: Representative | C31: LDA 1 | D31: Medication and Psychiatric Treatment Management | E31: 0.4703 | F31: 1 | G31: Treatment & Medication | H31: 0
A32: QDA-032 | B32: Ambiguous LDA | C32: LDA 2 | D32: Anxiety, Panic, and Somatic Symptoms | E32: 0.3555 | F32: 1 | G32: Anxiety & Fear | H32: 2 | I32: Daily functioning, sleep, and physical/vegetative state | J32: Daily functioning, sleep, and physical/vegetative state
A33: QDA-033 | B33: Ambiguous LDA | C33: LDA 2 | D33: Anxiety, Panic, and Somatic Symptoms | E33: 0.2325 | F33: 1 | G33: Treatment & Medication | H33: 1 | J33: Help-seeking, coping, social support, and recovery
A34: QDA-034 | B34: Ambiguous LDA | C34: LDA 2 | D34: Anxiety, Panic, and Somatic Symptoms | E34: 0.3385 | F34: 3 | G34: Anxiety & Fear; Hopelessness & Loss of Interest; Treatment & Medication | H34: 1 | J34: Treatment, therapy, and medication
A35: QDA-035 | B35: Ambiguous LDA | C35: LDA 2 | D35: Anxiety, Panic, and Somatic Symptoms | E35: 0.3521 | F35: 1 | G35: Sleep & Physical Difficulties | H35: 1 | J35: Daily functioning, sleep, and physical/vegetative state
A36: QDA-036 | B36: Ambiguous LDA | C36: LDA 2 | D36: Anxiety, Panic, and Somatic Symptoms | E36: 0.3331 | F36: 3 | G36: Anxiety & Fear; Self-Harm & Suicidal Thoughts; Sleep & Physical Difficulties | H36: 2 | I36: Help-seeking, coping, social support, and recovery | J36: Help-seeking, coping, social support, and recovery
A37: QDA-037 | B37: GPT-covered | C37: LDA 2 | D37: Anxiety, Panic, and Somatic Symptoms | E37: 0.6388 | F37: 4 | G37: Alcohol & Substance Use; Anxiety & Fear; Sleep & Physical Difficulties; Treatment & Medication | H37: 1 | J37: Daily functioning, sleep, and physical/vegetative state
A38: QDA-038 | B38: GPT-covered | C38: LDA 2 | D38: Anxiety, Panic, and Somatic Symptoms | E38: 0.4605 | F38: 3 | G38: Anxiety & Fear; Sleep & Physical Difficulties; Work, Study & Financial Stress | H38: 2 | I38: Daily functioning, sleep, and physical/vegetative state | J38: Daily functioning, sleep, and physical/vegetative state
A39: QDA-040 | B39: GPT-covered | C39: LDA 2 | D39: Anxiety, Panic, and Somatic Symptoms | E39: 0.4696 | F39: 2 | G39: Anxiety & Fear; Help-Seeking, Coping & Support | H39: 1 | I39: Daily functioning, sleep, and physical/vegetative state
A40: QDA-041 | B40: GPT-covered | C40: LDA 2 | D40: Anxiety, Panic, and Somatic Symptoms | E40: 0.3666 | F40: 2 | G40: Anxiety & Fear; Sleep & Physical Difficulties | H40: 1 | I40: Daily functioning, sleep, and physical/vegetative state
A41: QDA-042 | B41: GPT-covered | C41: LDA 2 | D41: Anxiety, Panic, and Somatic Symptoms | E41: 0.487 | F41: 4 | G41: Anxiety & Fear; Sleep & Physical Difficulties; Treatment & Medication; Work, Study & Financial Stress | H41: 1 | I41: Daily functioning, sleep, and physical/vegetative state
A42: QDA-043 | B42: GPT-covered | C42: LDA 2 | D42: Anxiety, Panic, and Somatic Symptoms | E42: 0.4108 | F42: 3 | G42: Anxiety & Fear; Relationships & Isolation; Sleep & Physical Difficulties | H42: 1 | J42: Daily functioning, sleep, and physical/vegetative state
A43: QDA-044 | B43: GPT-covered | C43: LDA 2 | D43: Anxiety, Panic, and Somatic Symptoms | E43: 0.4388 | F43: 4 | G43: Anxiety & Fear; Recovery & Resilience; Sleep & Physical Difficulties; Treatment & Medication | H43: 1 | I43: Help-seeking, coping, social support, and recovery
A44: QDA-045 | B44: GPT-covered | C44: LDA 2 | D44: Anxiety, Panic, and Somatic Symptoms | E44: 0.6919 | F44: 3 | G44: Anxiety & Fear; Sleep & Physical Difficulties; Treatment & Medication | H44: 1 | J44: Daily functioning, sleep, and physical/vegetative state
...

Sheet 210 GPT ANNOTATIONS
A1: QDA ID | B1: D1 / D2 | C1: GPT primary ID | D1: GPT primary theme | E1: GPT binary prediction | F1: GPT secondary theme | G1: MAXQDA codes n | H1: MAXQDA codes | I1: Work theme with public discussion
A2: QDA-001 | B2: D1 | C2: T08 | D2: Treatment, therapy, and medication | E2: 1 | F2: Alcohol and substance use | G2: 5 | H2: Alcohol & Substance Use; Anxiety & Fear; Recovery & Resilience; Self-Harm & Suicidal Thoughts; Treatment & Medication | I2: 0
A3: QDA-002 | B3: D1 | C3: T01 | D3: Emotions and feelings | E3: 1 | F3: Work, study, and financial/livelihood pressures | G3: 1 | H3: Public Discussion of Depression | I3: 0
A4: QDA-002 | B4: D2 | C4: T06 | D4: Work, study, and financial/livelihood pressures | E4: 1 | F4: Relationships and social connection | G4: 1 | H4: Public Discussion of Depression | I4: 1
A5: QDA-003 | B5: D2 | C5: T06 | D5: Work, study, and financial/livelihood pressures | E5: 1 | F5: Emotions and feelings | G5: 1 | H5: Public Discussion of Depression | I5: 1
A6: QDA-004 | B6: D2 | C6: T08 | D6: Treatment, therapy, and medication | E6: 0 | F6: NONE | G6: 1 | H6: Treatment & Medication | I6: 0
A7: QDA-005 | B7: D1 | C7: T08 | D7: Treatment, therapy, and medication | E7: 1 | F7: NONE | G7: 1 | H7: Treatment & Medication | I7: 0
A8: QDA-006 | B8: D2 | C8: T08 | D8: Treatment, therapy, and medication | E8: 1 | F8: Emotions and feelings | G8: 1 | H8: Treatment & Medication | I8: 0
A9: QDA-007 | B9: D1 | C9: T08 | D9: Treatment, therapy, and medication | E9: 0 | F9: Daily functioning, sleep, and physical/vegetative state | G9: 1 | H9: Treatment & Medication | I9: 0
A10: QDA-008 | B10: D1 | C10: T08 | D10: Treatment, therapy, and medication | E10: 1 | F10: Self-harm and suicidality | G10: 3 | H10: Help-Seeking, Coping & Support; Self-Harm & Suicidal Thoughts; Treatment & Medication | I10: 0
A11: QDA-009 | B11: D1 | C11: T08 | D11: Treatment, therapy, and medication | E11: 1 | F11: Daily functioning, sleep, and physical/vegetative state | G11: 2 | H11: Sleep & Physical Difficulties; Treatment & Medication | I11: 0
A12: QDA-010 | B12: D2 | C12: T11 | D12: Self-harm and suicidality | E12: 1 | F12: Treatment, therapy, and medication | G12: 1 | H12: Treatment & Medication | I12: 0
A13: QDA-011 | B13: D2 | C13: T08 | D13: Treatment, therapy, and medication | E13: 1 | F13: Emotions and feelings | G13: 2 | H13: Anxiety & Fear; Treatment & Medication | I13: 0
... A211: QDA-244 | B211: D1 | C211: T03 | D211: Motivation, hope/hopelessness, and purpose | E211: 1 | F211: Self-perception and cognitive patterns | G211: 2 | H211: Emotional Distress; Hopelessness & Loss of Interest | I211: 0

Sheet 14 EXCLUDED TEXTS
A1: QDA ID | B1: LDA topic | C1: LDA topic label | D1: GPT records | E1: Coding at exclusion | F1: Methodological note
A2: QDA-019 | B2: LDA 1 | C2: Medication and Psychiatric Treatment Management | D2: 0 | E2: No MAXQDA coded segments in revised 245-text project | F2: Excluded after coding review; report transparently
A3: QDA-039 | B3: LDA 2 | C3: Anxiety, Panic, and Somatic Symptoms | D3: 1 | E3: No MAXQDA coded segments in revised 245-text project | F3: Excluded after coding review; report transparently
A4: QDA-059 | B4: LDA 2 | C4: Anxiety, Panic, and Somatic Symptoms | D4: 2 | E4: No MAXQDA coded segments in revised 245-text project | F4: Excluded after coding review; report transparently
A5: QDA-061 | B5: LDA 2 | C5: Anxiety, Panic, and Somatic Symptoms | D5: 1 | E5: No MAXQDA coded segments in revised 245-text project | F5: Excluded after coding review; report transparently
A6: QDA-064 | B6: LDA 2 | C6: Anxiety, Panic, and Somatic Symptoms | D6: 1 | E6: No MAXQDA coded segments in revised 245-text project | F6: Excluded after coding review; report transparently
A7: QDA-071 | B7: LDA 2 | C7: Anxiety, Panic, and Somatic Symptoms | D7: 1 | E7: No MAXQDA coded segments in revised 245-text project | F7: Excluded after coding review; report transparently
A8: QDA-090 | B8: LDA 3 | C8: Psychosocial Stressors and Functional Impairment | D8: 1 | E8: No MAXQDA coded segments in revised 245-text project | F8: Excluded after coding review; report transparently
A9: QDA-136 | B9: LDA 5 | C9: Help-Seeking, Mental-Health Information, and Community Support | D9: 1 | E9: No MAXQDA coded segments in revised 245-text project | F9: Excluded after coding review; report transparently
A10: QDA-139 | B10: LDA 5 | C10: Help-Seeking, Mental-Health Information, and Community Support | D10: 2 | E10: No MAXQDA coded segments in revised 245-text project | F10: Excluded after coding review; report transparently
A11: QDA-149 | B11: LDA 5 | C11: Help-Seeking, Mental-Health Information, and Community Support | D11: 1 | E11: No MAXQDA coded segments in revised 245-text project | F11: Excluded after coding review; report transparently
A12: QDA-157 | B12: LDA 5 | C12: Help-Seeking, Mental-Health Information, and Community Support | D12: 1 | E12: No MAXQDA coded segments in revised 245-text project | F12: Excluded after coding review; report transparently
A13: QDA-185 | B13: LDA 6 | C13: Event-Specific Social-Media Commentary and Depression Trivialization | D13: 0 | E13: No MAXQDA coded segments in revised 245-text project | F13: Excluded after coding review; report transparently
... A15: QDA-221 | B15: LDA 7 | C15: Severe Depressive Distress, Hopelessness, and Suicidality | D15: 1 | E15: No MAXQDA coded segments in revised 245-text project | F15: Excluded after coding review; report transparently

Sheet METHODS AND CAVEATS
A1: Item | B1: How to interpret / report
A2: Human codebook | B2: The corresponding researcher reports the 15-category codebook was human-developed; 523 initially AI-assisted code assignments were subsequently validated by the researcher.
A3: Archival provenance | B3: The provided QDPX contains historical text and coding memos describing AI-assisted preliminary assignments; do not interpret them as a stored record of human sign-off.
A4: Sample flow | B4: Original purposive Label 1 sample: n=245. Excluded as uncoded: n=14. Final MAXQDA-coded subset: n=231.
A5: Selection sensitivity | B5: Removing uncoded texts raises some within-topic percentages without adding a coded match. Keep the original-sample comparison as a sensitivity analysis.
A6: LDA comparison | B6: LDA 7 dominant topics are used for partitioning. A text can have several MAXQDA codes, so code columns can overlap.
A7: GPT coverage | B7: 182 unique retained texts have GPT annotations; 154 have one, 28 have two. 210 model-source records total. 49 lack annotations.
A8: GPT counting | B8: GPT table overlaps are annotation-record counts. A text can contribute two records, so percentages are not independent-observation estimates.
A9: Convergence terminology | B9: Report descriptive thematic correspondence / overlap. No clinical validity, independent validation, or model agreement coefficient established by these cross-tabulations.
A10: Potentially divergent theme | B10: GPT T06 work/study/financial pressure matches Work, Study & Financial Stress in only 4/15 annotation records; 8/15 also have Public Discussion of Depression code.
A11: Code cloud | B11: Regenerate from the final 231-text, 15-code project; earlier 245-text visualizations and citations must be updated.
A12: Numerical consistency | B12: LDA overlap numerators and GPT overlaps are unchanged from the 245-case analysis because all 14 excluded texts had no MAXQDA assignments.
A13: Ethics | B13: The text labels are not clinical diagnoses. Review potentially identifying excerpts and translation accuracy before publication.
